Workbook

Sheet L1 fruit
A2: 2025005 - FOURNITURE DE DENREES ALIMENTAIRES - COMMUNE DE SAVERDUN - LOT 01 FRUITS
A4: BORDEREAU DES PRIX VALANT DETAIL ESTIMATIF
A6: N° | B6: PRODUIT | C6: PRIX UNITAIRE HT PAR UNITE | D6: QUANTITES ESTIMATIVES / AN | E6: UNITE | F6: PRIX TOTAL ESTIMATIF ANNUEL HT
A7: 1-1 | B7: ABRICOTS | C7: 0 | D7: 50 | E7: KG | F7: =+C7*D7 -> 0 | H7: JOURS DE COMMANDE | I7: LUNDI | J7: MARDI | K7: MERCREDI | L7: JEUDI | M7: VENDREDI
A8: 1-2 | B8: AVOCATS | C8: 0 | D8: 20 | E8: KG | F8: =+C8*D8 -> 0 | H8: JOURS DE LIVRAISONS | I8: LUNDI | J8: MARDI | K8: MERCREDI | L8: JEUDI | M8: VENDREDI
A9: 1-3 | B9: BANANES | C9: 0 | D9: 200 | E9: KG | F9: =+C9*D9 -> 0
A10: 1-4 | B10: CITRONS JAUNES | C10: 0 | D10: 40 | E10: KG | F10: =+C10*D10 -> 0
A11: 1-5 | B11: CLEMENTINES | C11: 0 | D11: =500*60% -> 300 | E11: KG | F11: =+C11*D11 -> 0
A12: 1-6 | B12: FRAISES BARQUETTE | C12: 0 | D12: 100 | E12: KG | F12: =+C12*D12 -> 0
A13: 1-7 | B13: KIWIS | C13: 0 | D13: 50 | E13: KG | F13: =+C13*D13 -> 0
A14: 1-8 | B14: MELONS | C14: 0 | D14: 50 | E14: KG | F14: =+C14*D14 -> 0
A15: 1-9 | B15: NECTARINES BLANCHES / JAUNES | C15: 0 | D15: 50 | E15: KG | F15: =+C15*D15 -> 0
A16: 1-10 | B16: ORANGES | C16: 0 | D16: 100 | E16: KG | F16: =+C16*D16 -> 0
A17: 1-11 | B17: PASTEQUES | C17: 0 | D17: 50 | E17: KG | F17: =+C17*D17 -> 0
A18: 1-12 | B18: PECHES BLANCHES / JAUNES | C18: 0 | D18: 80 | E18: KG | F18: =+C18*D18 -> 0
A19: 1-13 | B19: POIRES | C19: 0 | D19: 50 | E19: KG | F19: =+C19*D19 -> 0
A20: 1-14 | B20: POMME | C20: 0 | D20: 80 | E20: KG | F20: =+C20*D20 -> 0
A21: 1-15 | B21: RAISIN BLANC / ROUGE | C21: 0 | D21: 50 | E21: KG | F21: =+C21*D21 -> 0
B22: PRIX TOTAL ESTIMATIF ANNUEL HT | F22: =+SUM(F7:F21) -> 0
B23: TVA (5,5%) | F23: =+F22*0.055 -> 0
B24: PRIX TOTAL ESTIMATIF ANNUEL TTC | F24: =+F22+F23 -> 0

Sheet L2 fruits_AB
A2: 2025005 - FOURNITURE DE DENREES ALIMENTAIRES - COMMUNE DE SAVERDUN - LOT 02 FRUITS AB
A4: BORDEREAU DES PRIX VALANT DETAIL ESTIMATIF
A6: N° | B6: PRODUIT | C6: PRIX UNITAIRE HT PAR UNITE | D6: QUANTITES ESTIMATIVES / AN | E6: UNITE | F6: PRIX TOTAL ESTIMATIF ANNUEL HT
A7: 2-1 | B7: ABRICOTS AB | C7: 0 | D7: 50 | E7: KG | F7: =+C7*D7 -> 0 | H7: JOURS DE COMMANDE | I7: LUNDI | J7: MARDI | K7: MERCREDI | L7: JEUDI | M7: VENDREDI
A8: 2-2 | B8: AVOCATS AB | C8: 0 | D8: 20 | E8: KG | F8: =+C8*D8 -> 0 | H8: JOURS DE LIVRAISONS | I8: LUNDI | J8: MARDI | K8: MERCREDI | L8: JEUDI | M8: VENDREDI
A9: 2-3 | B9: BANANES AB | C9: 0 | D9: 800 | E9: KG | F9: =+C9*D9 -> 0
A10: 2-4 | B10: CITRONS JAUNES AB | C10: 0 | D10: 40 | E10: KG | F10: =+C10*D10 -> 0
A11: 2-5 | B11: CLEMENTINES AB | C11: 0 | D11: =500*40% -> 200 | E11: KG | F11: =+C11*D11 -> 0
A12: 2-6 | B12: FRAISES AB | C12: 0 | D12: 70 | E12: KG | F12: =+C12*D12 -> 0
A13: 2-7 | B13: KIWIS AB | C13: 0 | D13: 150 | E13: KG | F13: =+C13*D13 -> 0
A14: 2-8 | B14: MELONS AB | C14: 0 | D14: 250 | E14: KG | F14: =+C14*D14 -> 0
A15: 2-9 | B15: NECTARINES BLANCHES/JAUNES AB | C15: 0 | D15: 100 | E15: KG | F15: =+C15*D15 -> 0
A16: 2-10 | B16: ORANGES AB | C16: 0 | D16: 100 | E16: KG | F16: =+C16*D16 -> 0
A17: 2-11 | B17: PASTEQUES AB | C17: 0 | D17: 80 | E17: KG | F17: =+C17*D17 -> 0
A18: 2-12 | B18: PECHES JAUNES / BLANCHES AB | C18: 0 | D18: 120 | E18: KG | F18: =+C18*D18 -> 0
A19: 2-13 | B19: POIRES AB | C19: 0 | D19: 150 | E19: KG | F19: =+C19*D19 -> 0
A20: 2-14 | B20: POMME AB | C20: 0 | D20: 320 | E20: KG | F20: =+C20*D20 -> 0
A21: 2-15 | B21: RAISIN BLANC / ROUGE AB | C21: 0 | D21: 150 | E21: KG | F21: =+C21*D21 -> 0
B22: PRIX TOTAL ESTIMATIF ANNUEL HT | F22: =+SUM(F7:F21) -> 0
B23: TVA (5,5%) | F23: =+F22*0.055 -> 0
B24: PRIX TOTAL ESTIMATIF ANNUEL TTC | F24: =+F22+F23 -> 0

Sheet L3 lég
A2: 2025005 - FOURNITURE DE DENREES ALIMENTAIRES - COMMUNE DE SAVERDUN - LOT 03 LEGUMES
A4: BORDEREAU DES PRIX VALANT DETAIL ESTIMATIF
A6: N° | B6: PRODUIT | C6: PRIX UNITAIRE HT PAR UNITE | D6: QUANTITES ESTIMATIVES / AN | E6: UNITE | F6: PRIX TOTAL ESTIMATIF ANNUEL HT
A7: 3-1 | B7: SALADE | C7: 0 | D7: 100 | E7: KG | F7: =+D7*C7 -> 0 | H7: JOURS DE COMMANDE | I7: LUNDI | J7: MARDI | K7: MERCREDI | L7: JEUDI | M7: VENDREDI
A8: 3-2 | B8: ENDIVES | C8: 0 | D8: 20 | E8: KG | F8: =+D8*C8 -> 0 | H8: JOURS DE LIVRAISONS | I8: LUNDI | J8: MARDI | K8: MERCREDI | L8: JEUDI | M8: VENDREDI
A9: 3-3 | B9: CAROTTES | C9: 0 | D9: 200 | E9: KG | F9: =+D9*C9 -> 0
A10: 3-4 | B10: CELERI BRANCHE | C10: 0 | D10: 20 | E10: KG | F10: =+D10*C10 -> 0
A11: 3-5 | B11: CELERI RAVE | C11: 0 | D11: 60 | E11: KG | F11: =+D11*C11 -> 0
A12: 3-6 | B12: CHOU BLANC ou ROUGE | C12: 0 | D12: 40 | E12: KG | F12: =+D12*C12 -> 0
A13: 3-7 | B13: CHOU VERT | C13: 0 | D13: 20 | E13: KG | F13: =+D13*C13 -> 0
A14: 3-8 | B14: CHOU-FLEUR | C14: 0 | D14: 20 | E14: KG | F14: =+D14*C14 -> 0
A15: 3-9 | B15: COURGETTES | C15: 0 | D15: 35 | E15: KG | F15: =+D15*C15 -> 0
A16: 3-10 | B16: CONCOMBRES | C16: 0 | D16: 150 | E16: KG | F16: =+D16*C16 -> 0
A17: 3-11 | B17: CHAMPIGNONS | C17: 0 | D17: 10 | E17: KG | F17: =+D17*C17 -> 0
A18: 3-12 | B18: EPINARDS | C18: 0 | D18: 10 | E18: KG | F18: =+D18*C18 -> 0
A19: 3-13 | B19: FENOUIL | C19: 0 | D19: 20 | E19: KG | F19: =+D19*C19 -> 0
A20: 3-14 | B20: NAVETS | C20: 0 | D20: 10 | E20: KG | F20: =+D20*C20 -> 0
... A33: 3-27 | B33: AUBERGINES | C33: 0 | D33: 10 | E33: KG | F33: =+D33*C33 -> 0
B34: PRIX TOTAL ESTIMATIF ANNUEL HT | F34: =+SUM(F7:F33) -> 0
B35: TVA (5,5%) | F35: =+F34*0.055 -> 0
B36: PRIX TOTAL ESTIMATIF ANNUEL TTC | F36: =+F34+F35 -> 0

Sheet L4 lég_AB
A2: 2025005 - FOURNITURE DE DENREES ALIMENTAIRES - COMMUNE DE SAVERDUN - LOT 04 LEGUMES AB
A4: BORDEREAU DES PRIX VALANT DETAIL ESTIMATIF
A6: N° | B6: PRODUIT | C6: PRIX UNITAIRE HT PAR UNITE | D6: QUANTITES ESTIMATIVES / AN | E6: UNITE | F6: PRIX TOTAL ESTIMATIF ANNUEL HT
A7: 4-1 | B7: AUBERGINE AB | C7: 0 | D7: 35 | E7: KG | F7: =+D7*C7 -> 0 | H7: JOURS DE COMMANDE | I7: LUNDI | J7: MARDI | K7: MERCREDI | L7: JEUDI | M7: VENDREDI
A8: 4-2 | B8: CAROTTE AB | C8: 0 | D8: 400 | E8: KG | F8: =+D8*C8 -> 0 | H8: JOURS DE LIVRAISONS | I8: LUNDI | J8: MARDI | K8: MERCREDI | L8: JEUDI | M8: VENDREDI
A9: 4-3 | B9: CELERI BRANCHE AB | C9: 0 | D9: 30 | E9: KG | F9: =+D9*C9 -> 0
A10: 4-4 | B10: CELERIE RAVE AB | C10: 0 | D10: 120 | E10: KG | F10: =+D10*C10 -> 0
A11: 4-5 | B11: CHOUX ROUGES OU BLANCS AB | C11: 0 | D11: 80 | E11: KG | F11: =+D11*C11 -> 0
A12: 4-6 | B12: CHOUX VERTS AB | C12: 0 | D12: 30 | E12: KG | F12: =+D12*C12 -> 0
A13: 4-7 | B13: CHOUX FLEURS AB | C13: 0 | D13: 30 | E13: KG | F13: =+D13*C13 -> 0
A14: 4-8 | B14: CONCOMBRE AB | C14: 0 | D14: 250 | E14: KG | F14: =+D14*C14 -> 0
A15: 4-9 | B15: COURGETTE AB | C15: 0 | D15: 100 | E15: KG | F15: =+D15*C15 -> 0
A16: 4-10 | B16: CHAMPIGNON AB | C16: 0 | D16: 30 | E16: KG | F16: =+D16*C16 -> 0
A17: 4-11 | B17: EPINARDS AB | C17: 0 | D17: 15 | E17: KG | F17: =+D17*C17 -> 0
A18: 4-12 | B18: NAVET AB | C18: 0 | D18: 50 | E18: KG | F18: =+D18*C18 -> 0
A19: 4-13 | B19: OIGNONS AB | C19: 0 | D19: 10 | E19: KG | F19: =+D19*C19 -> 0
A20: 4-14 | B20: ECHALOTTE AB | C20: 0 | D20: 10 | E20: KG | F20: =+D20*C20 -> 0
... A31: 4-25 | B31: POMME DE TERRE AB | C31: 0 | D31: 400 | E31: KG | F31: =+D31*C31 -> 0
B32: PRIX TOTAL ESTIMATIF ANNUEL HT | F32: =+SUM(F7:F31) -> 0
B33: TVA (5,5%) | F33: =+F32*0.055 -> 0
B34: PRIX TOTAL ESTIMATIF ANNUEL TTC | F34: =+F32+F33 -> 0

Sheet L5 ovin
A2: 2025005 - FOURNITURE DE DENREES ALIMENTAIRES - COMMUNE DE SAVERDUN - LOT 05 VIANDE OVINE
A4: BORDEREAU DES PRIX VALANT DETAIL ESTIMATIF
A6: N° | B6: PRODUIT | C6: PRIX UNITAIRE HT PAR UNITE | D6: QUANTITES ESTIMATIVES / AN | E6: UNITE | F6: PRIX TOTAL ESTIMATIF ANNUEL HT
A7: 5-1 | B7: SAUTE AGNEAU | C7: 0 | D7: 100 | E7: KG | F7: =+D7*C7 -> 0 | H7: JOURS DE COMMANDE | I7: LUNDI | J7: MARDI | K7: MERCREDI | L7: JEUDI | M7: VENDREDI
B8: PRIX TOTAL ESTIMATIF ANNUEL HT | F8: =SUM(F7) -> 0 | H8: JOURS DE LIVRAISONS | I8: LUNDI | J8: MARDI | K8: MERCREDI | L8: JEUDI | M8: VENDREDI
B9: TVA (5,5%) | F9: =+F8*0.055 -> 0
B10: PRIX TOTAL ESTIMATIF ANNUEL TTC | F10: =+F8+F9 -> 0

Sheet L6 ovin_AB
A2: 2025005 - FOURNITURE DE DENREES ALIMENTAIRES - COMMUNE DE SAVERDUN - LOT 06 VIANDE OVINE AB
A4: BORDEREAU DES PRIX VALANT DETAIL ESTIMATIF
A6: N° | B6: PRODUIT | C6: PRIX UNITAIRE HT PAR UNITE | D6: QUANTITES ESTIMATIVES / AN | E6: UNITE | F6: PRIX TOTAL ESTIMATIF ANNUEL HT
A7: 6-1 | B7: SAUTE AGNEAU AB | C7: 0 | D7: 100 | E7: KG | F7: =+D7*C7 -> 0 | H7: JOURS DE COMMANDE | I7: LUNDI | J7: MARDI | K7: MERCREDI | L7: JEUDI | M7: VENDREDI
B8: PRIX TOTAL ESTIMATIF ANNUEL HT | F8: =SUM(F7) -> 0 | H8: JOURS DE LIVRAISONS | I8: LUNDI | J8: MARDI | K8: MERCREDI | L8: JEUDI | M8: VENDREDI
B9: TVA (5,5%) | F9: =+F8*0.055 -> 0
B10: PRIX TOTAL ESTIMATIF ANNUEL TTC | F10: =+F8+F9 -> 0

Sheet L7 bovin
A2: 2025005 - FOURNITURE DE DENREES ALIMENTAIRES - COMMUNE DE SAVERDUN - LOT 07 VIANDE BOVINE
A4: BORDEREAU DES PRIX VALANT DETAIL ESTIMATIF
A6: N° | B6: PRODUIT | C6: PRIX UNITAIRE HT PAR UNITE | D6: QUANTITES ESTIMATIVES / AN | E6: UNITE | F6: PRIX TOTAL ESTIMATIF ANNUEL HT
A7: 7-1 | B7: SAUTE VEAU BLANQUETTE (25/40G) | C7: 0 | D7: 150 | E7: KG | F7: =+C7*D7 -> 0 | H7: JOURS DE COMMANDE | I7: LUNDI | J7: MARDI | K7: MERCREDI | L7: JEUDI | M7: VENDREDI
A8: 7-2 | B8: SAUTE/BOURGUIGNON BŒUF (25/40G) | C8: 0 | D8: 80 | E8: KG | F8: =+C8*D8 -> 0 | H8: JOURS DE LIVRAISONS | I8: LUNDI | J8: MARDI | K8: MERCREDI | L8: JEUDI | M8: VENDREDI
A9: 7-3 | B9: HACHE VEAU | C9: 0 | D9: 20 | E9: KG | F9: =+C9*D9 -> 0
A10: 7-4 | B10: HACHE BŒUF | C10: 0 | D10: 20 | E10: KG | F10: =+C10*D10 -> 0
A11: 7-5 | B11: STEACK HACHE BŒUF (80/120G) | C11: 0 | D11: 20 | E11: KG | F11: =+C11*D11 -> 0
B12: PRIX TOTAL ESTIMATIF ANNUEL HT | F12: =+SUM(F7:F11) -> 0
B13: TVA (5,5%) | F13: =+F12*0.055 -> 0
B14: PRIX TOTAL ESTIMATIF ANNUEL TTC | F14: =+F12+F13 -> 0

Sheet L8 bovin_AB
A2: 2025005 - FOURNITURE DE DENREES ALIMENTAIRES - COMMUNE DE SAVERDUN - LOT 08 VIANDE BOVINE AB
A4: BORDEREAU DES PRIX VALANT DETAIL ESTIMATIF
A6: N° | B6: PRODUIT | C6: PRIX UNITAIRE HT PAR UNITE | D6: QUANTITES ESTIMATIVES / AN | E6: UNITE | F6: PRIX TOTAL ESTIMATIF ANNUEL HT
A7: 8-1 | B7: SAUTE VEAU BLANQUETTE AB (25/40G) | C7: 0 | D7: 150 | E7: KG | F7: =+C7*D7 -> 0 | H7: JOURS DE COMMANDE | I7: LUNDI | J7: MARDI | K7: MERCREDI | L7: JEUDI | M7: VENDREDI
A8: 8-2 | B8: SAUTE/BOURGUIGNON BŒUF AB (25/40G) | C8: 0 | D8: 80 | E8: KG | F8: =+C8*D8 -> 0 | H8: JOURS DE LIVRAISONS | I8: LUNDI | J8: MARDI | K8: MERCREDI | L8: JEUDI | M8: VENDREDI
A9: 8-3 | B9: HACHE VEAU AB | C9: 0 | D9: 20 | E9: KG | F9: =+C9*D9 -> 0
A10: 8-4 | B10: HACHE BŒUF AB | C10: 0 | D10: 20 | E10: KG | F10: =+C10*D10 -> 0
A11: 8-5 | B11: STEACK HACHE BŒUF AB (80/120G) | C11: 0 | D11: 20 | E11: KG | F11: =+C11*D11 -> 0
B12: PRIX TOTAL ESTIMATIF ANNUEL HT | F12: =+SUM(F7:F11) -> 0
B13: TVA (5,5%) | F13: =+F12*0.055 -> 0
B14: PRIX TOTAL ESTIMATIF ANNUEL TTC | F14: =+F12+F13 -> 0

Sheet L9 porc
A2: 2025005 - FOURNITURE DE DENREES ALIMENTAIRES - COMMUNE DE SAVERDUN - LOT 09 VIANDE PORC ET CHARCUTERIE
A4: BORDEREAU DES PRIX VALANT DETAIL ESTIMATIF
A6: N° | B6: PRODUIT | C6: PRIX UNITAIRE HT PAR UNITE | D6: QUANTITES ESTIMATIVES / AN | E6: UNITE | F6: PRIX TOTAL ESTIMATIF ANNUEL HT
A7: 9-1 | B7: SAUCISSE DE PORC | C7: 0 | D7: 85 | E7: KG | F7: =+C7*D7 -> 0 | H7: JOURS DE COMMANDE | I7: LUNDI | J7: MARDI | K7: MERCREDI | L7: JEUDI | M7: VENDREDI
A8: 9-2 | B8: ESCALOPE DE PORC | C8: 0 | D8: 30 | E8: KG | F8: =+C8*D8 -> 0 | H8: JOURS DE LIVRAISONS | I8: LUNDI | J8: MARDI | K8: MERCREDI | L8: JEUDI | M8: VENDREDI
A9: 9-3 | B9: SAUTE DE PORC | C9: 0 | D9: 20 | E9: KG | F9: =+C9*D9 -> 0
A10: 9-4 | B10: ROTI ECHINE | C10: 0 | D10: 20 | E10: KG | F10: =+C10*D10 -> 0
A11: 9-5 | B11: CHAIR A SAUCISSE | C11: 0 | D11: 20 | E11: KG | F11: =+C11*D11 -> 0
A12: 9-6 | B12: JAMBON BLANC | C12: 0 | D12: 30 | E12: KG | F12: =+C12*D12 -> 0
B13: PRIX TOTAL ESTIMATIF ANNUEL HT | F13: =+SUM(F7:F12) -> 0
B14: TVA (5,5%) | F14: =+F13*0.055 -> 0
B15: PRIX TOTAL ESTIMATIF ANNUEL TTC | F15: =+F13+F14 -> 0

Sheet L10 porc_AB
A2: 2025005 - FOURNITURE DE DENREES ALIMENTAIRES - COMMUNE DE SAVERDUN - LOT 10 VIANDE PORC ET CHARCUTERIE AB
A4: BORDEREAU DES PRIX VALANT DETAIL ESTIMATIF
A6: N° | B6: PRODUIT | C6: PRIX UNITAIRE HT PAR UNITE | D6: QUANTITES ESTIMATIVES / AN | E6: UNITE | F6: PRIX TOTAL ESTIMATIF ANNUEL HT
A7: 10-1 | B7: SAUCISSE DE PORC AB | C7: 0 | D7: 100 | E7: KG | F7: =+D7*C7 -> 0 | H7: JOURS DE COMMANDE | I7: LUNDI | J7: MARDI | K7: MERCREDI | L7: JEUDI | M7: VENDREDI
A8: 10-2 | B8: ESCALOPE DE PORC AB | C8: 0 | D8: 60 | E8: KG | F8: =+D8*C8 -> 0 | H8: JOURS DE LIVRAISONS | I8: LUNDI | J8: MARDI | K8: MERCREDI | L8: JEUDI | M8: VENDREDI
A9: 10-3 | B9: SAUTE DE PORC AB | C9: 0 | D9: 30 | E9: KG | F9: =+D9*C9 -> 0
A10: 10-4 | B10: ROTI ECHINE AB | C10: 0 | D10: 30 | E10: KG | F10: =+D10*C10 -> 0
A11: 10-5 | B11: CHAIR A SAUCISSE AB | C11: 0 | D11: 20 | E11: KG | F11: =+D11*C11 -> 0
A12: 10-6 | B12: JAMBON BLANC AB | C12: 0 | D12: 30 | E12: KG | F12: =+D12*C12 -> 0
B13: PRIX TOTAL ESTIMATIF ANNUEL HT | F13: =+SUM(F7:F12) -> 0
B14: TVA (5,5%) | F14: =+F13*0.055 -> 0
B15: PRIX TOTAL ESTIMATIF ANNUEL TTC | F15: =+F13+F14 -> 0

Sheet L11 vol
A2: 2025005 - FOURNITURE DE DENREES ALIMENTAIRES - COMMUNE DE SAVERDUN - LOT 11 VIANDE VOLAILLE
A4: BORDEREAU DES PRIX VALANT DETAIL ESTIMATIF
A6: N° | B6: PRODUIT | C6: PRIX UNITAIRE HT PAR UNITE | D6: QUANTITES ESTIMATIVES / AN | E6: UNITE | F6: PRIX TOTAL ESTIMATIF ANNUEL HT
A7: 11-1 | B7: SAUTE POULET | C7: 0 | D7: 185 | E7: KG | F7: =+C7*D7 -> 0 | H7: JOURS DE COMMANDE | I7: LUNDI | J7: MARDI | K7: MERCREDI | L7: JEUDI | M7: VENDREDI
A8: 11-2 | B8: HAUT DE CUISSE | C8: 0 | D8: 100 | E8: KG | F8: =+C8*D8 -> 0 | H8: JOURS DE LIVRAISONS | I8: LUNDI | J8: MARDI | K8: MERCREDI | L8: JEUDI | M8: VENDREDI
A9: 11-3 | B9: PILON POULET | C9: 0 | D9: 100 | E9: KG | F9: =+C9*D9 -> 0
A10: 11-4 | B10: POULET PAC ENTIER | C10: 0 | D10: 15 | E10: KG | F10: =+C10*D10 -> 0
B11: PRIX TOTAL ESTIMATIF ANNUEL HT | F11: =+SUM(F7:F10) -> 0
B12: TVA (5,5%) | F12: =+F11*0.055 -> 0
B13: PRIX TOTAL ESTIMATIF ANNUEL TTC | F13: =+F11+F12 -> 0

Sheet L12 vol_AB
A2: 2025005 - FOURNITURE DE DENREES ALIMENTAIRES - COMMUNE DE SAVERDUN - LOT 12 VIANDE VOLAILLE AB
A4: BORDEREAU DES PRIX VALANT DETAIL ESTIMATIF
A6: N° | B6: PRODUIT | C6: PRIX UNITAIRE HT PAR UNITE | D6: QUANTITES ESTIMATIVES / AN | E6: UNITE | F6: PRIX TOTAL ESTIMATIF ANNUEL HT
A7: 12-1 | B7: SAUTE POULET AB | C7: 0 | D7: 185 | E7: KG | F7: =+C7*D7 -> 0 | H7: JOURS DE COMMANDE | I7: LUNDI | J7: MARDI | K7: MERCREDI | L7: JEUDI | M7: VENDREDI
A8: 12-2 | B8: HAUT DE CUISSE AB | C8: 0 | D8: 100 | E8: KG | F8: =+C8*D8 -> 0 | H8: JOURS DE LIVRAISONS | I8: LUNDI | J8: MARDI | K8: MERCREDI | L8: JEUDI | M8: VENDREDI
A9: 12-3 | B9: PILON POULET AB | C9: 0 | D9: 100 | E9: KG | F9: =+C9*D9 -> 0
A10: 12-4 | B10: POULET PAC ENTIER AB | C10: 0 | D10: 15 | E10: KG | F10: =+C10*D10 -> 0
B11: PRIX TOTAL ESTIMATIF ANNUEL HT | F11: =+SUM(F7:F10) -> 0
B12: TVA (5,5%) | F12: =+F11*0.055 -> 0
B13: PRIX TOTAL ESTIMATIF ANNUEL TTC | F13: =+F11+F12 -> 0

Sheet L13_legumin_huile_AB
A2: 2025005 - FOURNITURE DE DENREES ALIMENTAIRES - COMMUNE DE SAVERDUN - LOT 13 LEGUMINEUSE ET HUILE AB
A4: BORDEREAU DES PRIX VALANT DETAIL ESTIMATIF
A6: N° | B6: PRODUIT | C6: PRIX UNITAIRE HT PAR UNITE | D6: QUANTITES ESTIMATIVES / AN | E6: UNITE | F6: PRIX TOTAL ESTIMATIF ANNUEL HT | G6: CONDITIONNEMENT PROPOSE | H6: PRIX h.T. DU CONDITIONNEMENT PROPOSE | I6: PRIX t.T.c DU CONDITIONNEMENT PROPOSE
A7: 13-1 | B7: HARICOT BLANCS | C7: 0 | D7: 10 | E7: KG | F7: =+C7*D7 -> 0 | G7: 0 | H7: 0 | I7: 0
A8: 13-2 | B8: LENTILLES | C8: 0 | D8: 17.5 | E8: KG | F8: =+C8*D8 -> 0 | G8: 0 | H8: 0 | I8: 0
A9: 13-3 | B9: POIS CHICHES | C9: 0 | D9: 3 | E9: KG | F9: =+C9*D9 -> 0 | G9: 0 | H9: 0 | I9: 0
A10: 13-4 | B10: HUILE TOURNESOL | C10: 0 | D10: 120 | E10: LITRES | F10: =+C10*D10 -> 0 | G10: 0 | H10: 0 | I10: 0
B11: PRIX TOTAL ESTIMATIF ANNUEL HT | F11: =+SUM(F7:F10) -> 0
B12: TVA (5,5%) | F12: =+F11*0.055 -> 0
B13: PRIX TOTAL ESTIMATIF ANNUEL TTC | F13: =+F11+F12 -> 0
B15: JOURS DE COMMANDE | C15: LUNDI | D15: MARDI | E15: MERCREDI | F15: JEUDI | G15: VENDREDI
B16: JOURS DE LIVRAISONS | C16: LUNDI | D16: MARDI | E16: MERCREDI | F16: JEUDI | G16: VENDREDI

Sheet L14_pate_fraich_ARTISANAL
A2: 2025005 - FOURNITURE DE DENREES ALIMENTAIRES - COMMUNE DE SAVERDUN - LOT 14 PATES FRAICHES ARTISANALES
A4: BORDEREAU DES PRIX VALANT DETAIL ESTIMATIF
A6: N° | B6: PRODUIT | C6: PRIX UNITAIRE HT PAR UNITE | D6: QUANTITES ESTIMATIVES / AN | E6: UNITE | F6: PRIX TOTAL ESTIMATIF ANNUEL HT | G6: CONDITIONNEMENT PROPOSE | H6: PRIX h.T. DU CONDITIONNEMENT PROPOSE | I6: PRIX t.T.c DU CONDITIONNEMENT PROPOSE
A7: 14-1 | B7: PATES FRAICHES LASAGNE | C7: 0 | D7: 50 | E7: KG | F7: =+C7*D7 -> 0 | H7: 0 | I7: 0
A8: 14-2 | B8: RAVIOLIS FRAIS | C8: 0 | D8: 100 | E8: KG | F8: =+C8*D8 -> 0 | H8: 0 | I8: 0
A9: 14-3 | B9: PATES FRAICHES | C9: 0 | D9: 100 | E9: KG | F9: =+C9*D9 -> 0 | H9: 0 | I9: 0
B10: PRIX TOTAL ESTIMATIF ANNUEL HT | F10: =+SUM(F7:F9) -> 0
B11: TVA (5,5%) | F11: =+F10*0.055 -> 0
B12: PRIX TOTAL ESTIMATIF ANNUEL TTC | F12: =+F10+F11 -> 0
B14: JOURS DE COMMANDE | C14: LUNDI | D14: MARDI | E14: MERCREDI | F14: JEUDI | G14: VENDREDI
B15: JOURS DE LIVRAISONS | C15: LUNDI | D15: MARDI | E15: MERCREDI | F15: JEUDI | G15: VENDREDI

Sheet L15_ yaourt_ab_fermiers
A2: 2025005 - FOURNITURE DE DENREES ALIMENTAIRES - COMMUNE DE SAVERDUN - LOT 15 YAOURTS FERMIERS AB
A4: BORDEREAU DES PRIX VALANT DETAIL ESTIMATIF
A6: N° | B6: PRODUIT | C6: PRIX UNITAIRE HT PAR UNITE | D6: QUANTITES ESTIMATIVES / AN | E6: UNITE | F6: PRIX TOTAL ESTIMATIF ANNUEL HT | G6: CONDITIONNEMENT PROPOSE | H6: PRIX h.T. DU CONDITIONNEMENT PROPOSE | I6: PRIX t.T.c DU CONDITIONNEMENT PROPOSE
A7: 15-1 | B7: YAOURT NATURE | C7: 0 | D7: 5000 | E7: POT 125 G | F7: =+C7*D7 -> 0 | H7: 0 | I7: 0
A8: 15-2 | B8: YAOURT NATURE SUCRE | C8: 0 | D8: 2500 | E8: POT 125 G | F8: =+C8*D8 -> 0 | H8: 0 | I8: 0
B9: PRIX TOTAL ESTIMATIF ANNUEL HT | F9: =+SUM(F7:F8) -> 0
B10: TVA (5,5%) | F10: =+F9*0.055 -> 0
B11: PRIX TOTAL ESTIMATIF ANNUEL TTC | F11: =+F9+F10 -> 0
B13: JOURS DE COMMANDE | C13: LUNDI | D13: MARDI | E13: MERCREDI | F13: JEUDI | G13: VENDREDI
B14: JOURS DE LIVRAISONS | C14: LUNDI | D14: MARDI | E14: MERCREDI | F14: JEUDI | G14: VENDREDI

Sheet L16_from_artisanal
A2: 2025005 - FOURNITURE DE DENREES ALIMENTAIRES - COMMUNE DE SAVERDUN - LOT 16 FROMAGES ARTISANAUX
A4: BORDEREAU DES PRIX VALANT DETAIL ESTIMATIF
A6: N° | B6: PRODUIT | C6: PRIX UNITAIRE HT PAR UNITE | D6: QUANTITES ESTIMATIVES / AN | E6: UNITE | F6: PRIX TOTAL ESTIMATIF ANNUEL HT | G6: CONDITIONNEMENT PROPOSE | H6: PRIX h.T. DU CONDITIONNEMENT PROPOSE | I6: PRIX t.T.c DU CONDITIONNEMENT PROPOSE
A7: 16-1 | B7: TOMME VACHE | C7: 0 | D7: 60 | E7: KG | F7: =+C7*D7 -> 0 | H7: 0 | I7: 0
A8: 16-2 | B8: SAINT PATERNE | C8: 0 | D8: 60 | E8: KG | F8: =+C8*D8 -> 0 | H8: 0 | I8: 0
A9: 16-3 | B9: TOMME CHEVRE FERMIERE | C9: 0 | D9: 60 | E9: KG | F9: =+C9*D9 -> 0 | H9: 0 | I9: 0
A10: 16-4 | B10: BETHMALE | C10: 0 | D10: 30 | E10: KG | F10: =+C10*D10 -> 0 | H10: 0 | I10: 0
B11: PRIX TOTAL ESTIMATIF ANNUEL HT | F11: =+SUM(F7:F10) -> 0
B12: TVA (5,5%) | F12: =+F11*0.055 -> 0
B13: PRIX TOTAL ESTIMATIF ANNUEL TTC | F13: =+F11+F12 -> 0
B15: JOURS DE COMMANDE | C15: LUNDI | D15: MARDI | E15: MERCREDI | F15: JEUDI | G15: VENDREDI
B16: JOURS DE LIVRAISONS | C16: LUNDI | D16: MARDI | E16: MERCREDI | F16: JEUDI | G16: VENDREDI

Sheet L17_from_artisanal _ab
A2: 2025005 - FOURNITURE DE DENREES ALIMENTAIRES - COMMUNE DE SAVERDUN - LOT 17 FROMAGES ARTISANAUX AB
A4: BORDEREAU DES PRIX VALANT DETAIL ESTIMATIF
A6: N° | B6: PRODUIT | C6: PRIX UNITAIRE HT PAR UNITE | D6: QUANTITES ESTIMATIVES / AN | E6: UNITE | F6: PRIX TOTAL ESTIMATIF ANNUEL HT | G6: CONDITIONNEMENT PROPOSE | H6: PRIX h.T. DU CONDITIONNEMENT PROPOSE | I6: PRIX t.T.c DU CONDITIONNEMENT PROPOSE
A7: 17-1 | B7: TOMME VACHE ab | C7: 0 | D7: 60 | E7: KG | F7: =+C7*D7 -> 0 | H7: 0 | I7: 0
A8: 17-2 | B8: SAINT PATERNE ab | C8: 0 | D8: 60 | E8: KG | F8: =+C8*D8 -> 0 | H8: 0 | I8: 0
A9: 17-3 | B9: TOMME CHEVRE FERMIERE ab | C9: 0 | D9: 60 | E9: KG | F9: =+C9*D9 -> 0 | H9: 0 | I9: 0
A10: 17-4 | B10: BETHMALE ab | C10: 0 | D10: 30 | E10: KG | F10: =+C10*D10 -> 0 | H10: 0 | I10: 0
B11: PRIX TOTAL ESTIMATIF ANNUEL HT | F11: =+SUM(F7:F10) -> 0
B12: TVA (5,5%) | F12: =+F11*0.055 -> 0
B13: PRIX TOTAL ESTIMATIF ANNUEL TTC | F13: =+F11+F12 -> 0
B15: JOURS DE COMMANDE | C15: LUNDI | D15: MARDI | E15: MERCREDI | F15: JEUDI | G15: VENDREDI
B16: JOURS DE LIVRAISONS | C16: LUNDI | D16: MARDI | E16: MERCREDI | F16: JEUDI | G16: VENDREDI

Sheet L18_PRODUIT_LAITIER_AB
A2: 2025005 - FOURNITURE DE DENREES ALIMENTAIRES - COMMUNE DE SAVERDUN - LOT 18 PRODUITS LAITIERS AB
A4: BORDEREAU DES PRIX VALANT DETAIL ESTIMATIF
A6: N° | B6: PRODUIT | C6: PRIX UNITAIRE HT PAR UNITE | D6: QUANTITES ESTIMATIVES / AN | E6: UNITE | F6: PRIX TOTAL ESTIMATIF ANNUEL HT | G6: CONDITIONNEMENT PROPOSE | H6: PRIX h.T. DU CONDITIONNEMENT PROPOSE | I6: PRIX t.T.c DU CONDITIONNEMENT PROPOSE
A7: 18-1 | B7: CREME FRAICHE EPAISSE - seau de 5 kg | C7: 0 | D7: 40 | E7: KG | F7: =+C7*D7 -> 0 | H7: 0 | I7: 0
A8: 18-2 | B8: CREME FRAICHE LIQUIDE - en 1 litre | C8: 0 | D8: 650 | E8: KG | F8: =+C8*D8 -> 0 | H8: 0 | I8: 0
A9: 18-3 | B9: FROMAGE BLANC en seau de 5 kg | C9: 0 | D9: 100 | E9: KG | F9: =+C9*D9 -> 0 | H9: 0 | I9: 0
A10: 18-4 | B10: LAIT en 1 litre | C10: 0 | D10: 600 | E10: KG | F10: =+C10*D10 -> 0 | H10: 0 | I10: 0
A11: 18-5 | B11: BEURRE DOUX plaquette 250g | C11: 0 | D11: 150 | E11: KG | F11: =+C11*D11 -> 0 | H11: 0 | I11: 0
A12: 18-6 | B12: BEURRE 1/2 SEL plaquette 250g | C12: 0 | D12: 20 | E12: KG | F12: =+C12*D12 -> 0 | H12: 0 | I12: 0
A13: 18-7 | B13: YAOURT NATURE 100GRS | C13: 0 | D13: 2500 | E13: UNITE | F13: =+C13*D13 -> 0 | H13: 0 | I13: 0
A14: 18-8 | B14: YAOURT NATURE 125GRS | C14: 0 | D14: 2500 | E14: UNITE | F14: =+C14*D14 -> 0 | H14: 0 | I14: 0
A15: 18-9 | B15: YAOURT AROMATISES (FRAISE, VANILLE…) 125 GRS | C15: 0 | D15: 500 | E15: UNTE | F15: =+C15*D15 -> 0 | H15: 0 | I15: 0
A16: 18-10 | B16: YAOURT NATURE EN SEAU 5kg | C16: 0 | D16: 10 | E16: unite | F16: =+C16*D16 -> 0 | H16: 0 | I16: 0
B17: PRIX TOTAL ESTIMATIF ANNUEL HT | F17: =+SUM(F7:F16) -> 0
B18: TVA (5,5%) | F18: =+F17*0.055 -> 0
B19: PRIX TOTAL ESTIMATIF ANNUEL TTC | F19: =+F17+F18 -> 0
B21: JOURS DE COMMANDE | C21: LUNDI | D21: MARDI | E21: MERCREDI | F21: JEUDI | G21: VENDREDI
B22: JOURS DE LIVRAISONS | C22: LUNDI | D22: MARDI | E22: MERCREDI | F22: JEUDI | G22: VENDREDI

Sheet L19_EPICERIE
A2: 2025005 - FOURNITURE DE DENREES ALIMENTAIRES - COMMUNE DE SAVERDUN - LOT 19 EPICERIE
A4: BORDEREAU DES PRIX VALANT DETAIL ESTIMATIF
A6: N° | B6: PRODUIT | C6: PRIX UNITAIRE HT PAR UNITE | D6: QUANTITES ESTIMATIVES / AN | E6: UNITE | F6: PRIX TOTAL ESTIMATIF ANNUEL HT | G6: CONDITIONNEMENT PROPOSE | H6: PRIX h.T. DU CONDITIONNEMENT PROPOSE | I6: PRIX t.T.c DU CONDITIONNEMENT PROPOSE
A7: 19-1 | B7: PATES BLANCHES | C7: 0 | D7: =L20_EPICERIE_AB!D7/4 -> 62.5 | E7: KG | F7: =+C7*D7 -> 0 | H7: 0 | I7: 0
A8: 19-2 | B8: PATES SEMI_COMPLETES | C8: 0 | D8: =L20_EPICERIE_AB!D8/4 -> 62.5 | E8: KG | F8: =+C8*D8 -> 0 | H8: 0 | I8: 0
A9: 19-3 | B9: SPAETZEL | C9: 0 | D9: =L20_EPICERIE_AB!D9/4 -> 12.5 | E9: KG | F9: =+C9*D9 -> 0 | H9: 0 | I9: 0
A10: 19-4 | B10: VERMICELLE | C10: 0 | D10: =L20_EPICERIE_AB!D10/4 -> 3.75 | E10: KG | F10: =+C10*D10 -> 0 | H10: 0 | I10: 0
A11: 19-5 | B11: CROZET | C11: 0 | D11: =L20_EPICERIE_AB!D11/4 -> 12.5 | E11: KG | F11: =+C11*D11 -> 0 | H11: 0 | I11: 0
A12: 19-6 | B12: RIZ BLANC | C12: 0 | D12: =L20_EPICERIE_AB!D12/4 -> 37.5 | E12: KG | F12: =+C12*D12 -> 0 | H12: 0 | I12: 0
A13: 19-7 | B13: RIZ SEMI-COMPLET | C13: 0 | D13: =L20_EPICERIE_AB!D13/4 -> 37.5 | E13: KG | F13: =+C13*D13 -> 0 | H13: 0 | I13: 0
A14: 19-8 | B14: RIZ CAMARGUE | C14: 0 | D14: =L20_EPICERIE_AB!D14/4 -> 50 | E14: KG | F14: =+C14*D14 -> 0 | H14: 0 | I14: 0
A15: 19-9 | B15: RIZ THAI | C15: 0 | D15: =L20_EPICERIE_AB!D15/4 -> 7.5 | E15: KG | F15: =+C15*D15 -> 0 | H15: 0 | I15: 0
A16: 19-10 | B16: RIZ BASMATI | C16: 0 | D16: =L20_EPICERIE_AB!D16/4 -> 7.5 | E16: KG | F16: =+C16*D16 -> 0 | H16: 0 | I16: 0
A17: 19-11 | B17: RIZ ROND RISOTTO | C17: 0 | D17: =L20_EPICERIE_AB!D17/4 -> 5 | E17: KG | F17: =+C17*D17 -> 0 | H17: 0 | I17: 0
A18: 19-12 | B18: SEMOULE | C18: 0 | D18: =L20_EPICERIE_AB!D18/4 -> 15 | E18: KG | F18: =+C18*D18 -> 0 | H18: 0 | I18: 0
... A25: 19-19 | B25: FARINE | C25: 0 | D25: =L20_EPICERIE_AB!D25/4 -> 12.5 | E25: KG | F25: =+C25*D25 -> 0 | H25: 0 | I25: 0
A26: 19-20 | B26: HUILE SESAME | C26: 0 | D26: 2 | E26: LITRES | F26: =+C26*D26 -> 0 | H26: 0 | I26: 0
A27: 19-21 | B27: HUILE DE NOIX | C27: 0 | D27: 2 | E27: LITRES | F27: =+C27*D27 -> 0 | H27: 0 | I27: 0
A28: 19-22 | B28: VINAIGRE BALSAMIQUE IGP | C28: 0 | D28: 60 | E28: LITRES | F28: =+C28*D28 -> 0 | H28: 0 | I28: 0
A29: 19-23 | B29: VINAIGRE DE VIN | C29: 0 | D29: 40 | E29: LITRES | F29: =+C29*D29 -> 0 | H29: 0 | I29: 0
A30: 19-24 | B30: VINAIGRE DE CIDRE | C30: 0 | D30: 30 | E30: LITRES | F30: =+C30*D30 -> 0 | H30: 0 | I30: 0
A31: 19-25 | B31: CHIPS | C31: 0 | D31: 400 | E31: KG | F31: =+C31*D31 -> 0 | H31: 0 | I31: 0
A32: 19-26 | B32: SEL FIN | C32: 0 | D32: 90 | E32: KG | F32: =+C32*D32 -> 0 | H32: 0 | I32: 0
A33: 19-27 | B33: THYM | C33: 0 | D33: 2 | E33: KG | F33: =+C33*D33 -> 0 | H33: 0 | I33: 0
A34: 19-28 | B34: LAURIER | C34: 0 | D34: 2 | E34: KG | F34: =+C34*D34 -> 0 | H34: 0 | I34: 0
A35: 19-29 | B35: ORIGAN | C35: 0 | D35: 2 | E35: KG | F35: =+C35*D35 -> 0 | H35: 0 | I35: 0
A36: 19-30 | B36: CURRY | C36: 0 | D36: 2 | E36: KG | F36: =+C36*D36 -> 0 | H36: 0 | I36: 0
A37: 19-31 | B37: CORIANDRE | C37: 0 | D37: 2 | E37: KG | F37: =+C37*D37 -> 0 | H37: 0 | I37: 0
... A51: 19-45 | B51: SARDINES EN BOITE | C51: 0 | D51: 15 | E51: KG | F51: =+C51*D51 -> 0 | H51: 0 | I51: 0
A52: 19-46 | B52: HARICOTS ROUGES 5/1 | C52: 0 | D52: =+L20_EPICERIE_AB!D34/4 -> 10 | E52: KG | F52: =+C52*D52 -> 0 | H52: 0 | I52: 0
A53: 19-47 | B53: POIS CHICHES APERIZES 5/1 | C53: 0 | D53: =+L20_EPICERIE_AB!D35/4 -> 10 | E53: KG | F53: =+C53*D53 -> 0 | H53: 0 | I53: 0
A54: 19-48 | B54: HARICOT BLANC 5/1 | C54: 0 | D54: =+L20_EPICERIE_AB!D36/4 -> 10 | E54: KG | F54: =+C54*D54 -> 0 | H54: 0 | I54: 0
A55: 19-49 | B55: POIS CHICHES SECS | C55: 0 | D55: 5 | E55: KG | F55: =+C55*D55 -> 0 | H55: 0 | I55: 0
A56: 19-50 | B56: POIS CASSES SECS | C56: 0 | D56: 5 | E56: KG | F56: =+C56*D56 -> 0 | H56: 0 | I56: 0
A57: 19-51 | B57: HARICOTS BLANCS SECS | C57: 0 | D57: 5 | E57: KG | F57: =+C57*D57 -> 0 | H57: 0 | I57: 0
A58: 19-52 | B58: LENTILLES SECHES | C58: 0 | D58: =+L20_EPICERIE_AB!D37/4 -> 10 | E58: KG | F58: =+C58*D58 -> 0 | H58: 0 | I58: 0
A59: 19-53 | B59: SUCRE BLOND | C59: 0 | D59: =+L20_EPICERIE_AB!D58/4 -> 12.5 | E59: KG | F59: =+C59*D59 -> 0 | H59: 0 | I59: 0
A60: 19-54 | B60: SUCRE BLANC | C60: 0 | D60: =+D59 -> 12.5 | E60: KG | F60: =+C60*D60 -> 0 | H60: 0 | I60: 0
A61: 19-55 | B61: LEVURE CHIMIQUE | C61: 0 | D61: 3 | E61: KG | F61: =+C61*D61 -> 0 | H61: 0 | I61: 0
A62: 19-56 | B62: GELATINE BOVINE | C62: 0 | D62: 3 | E62: KG | F62: =+C62*D62 -> 0 | H62: 0 | I62: 0
...

Sheet L20_EPICERIE_AB
A2: 2025005 - FOURNITURE DE DENREES ALIMENTAIRES - COMMUNE DE SAVERDUN - LOT 20 EPICERIE AB
A4: BORDEREAU DES PRIX VALANT DETAIL ESTIMATIF
A6: N° | B6: PRODUIT | C6: PRIX UNITAIRE HT PAR UNITE | D6: QUANTITES ESTIMATIVES / AN | E6: UNITE | F6: PRIX TOTAL ESTIMATIF ANNUEL HT | G6: CONDITIONNEMENT PROPOSE | H6: PRIX h.T. DU CONDITIONNEMENT PROPOSE | I6: PRIX t.T.c DU CONDITIONNEMENT PROPOSE
A7: 20-1 | B7: PATES BLANCHES | C7: 0 | D7: 250 | E7: KG | F7: =+C7*D7 -> 0 | H7: 0 | I7: 0
A8: 20-2 | B8: PATES SEMI_COMPLETES | C8: 0 | D8: 250 | E8: KG | F8: =+C8*D8 -> 0 | H8: 0 | I8: 0
A9: 20-3 | B9: SPAETZEL | C9: 0 | D9: 50 | E9: KG | F9: =+C9*D9 -> 0 | H9: 0 | I9: 0
A10: 20-4 | B10: VERMICELLE | C10: 0 | D10: 15 | E10: KG | F10: =+C10*D10 -> 0 | H10: 0 | I10: 0
A11: 20-5 | B11: CROZET | C11: 0 | D11: 50 | E11: KG | F11: =+C11*D11 -> 0 | H11: 0 | I11: 0
A12: 20-6 | B12: RIZ BLANC | C12: 0 | D12: 150 | E12: KG | F12: =+C12*D12 -> 0 | H12: 0 | I12: 0
A13: 20-7 | B13: RIZ SEMI-COMPLET | C13: 0 | D13: 150 | E13: KG | F13: =+C13*D13 -> 0 | H13: 0 | I13: 0
A14: 20-8 | B14: RIZ CAMARGUE | C14: 0 | D14: 200 | E14: KG | F14: =+C14*D14 -> 0 | H14: 0 | I14: 0
A15: 20-9 | B15: RIZ THAI | C15: 0 | D15: 30 | E15: KG | F15: =+C15*D15 -> 0 | H15: 0 | I15: 0
A16: 20-10 | B16: RIE BASMATI | C16: 0 | D16: 30 | E16: KG | F16: =+C16*D16 -> 0 | H16: 0 | I16: 0
A17: 20-11 | B17: RIZ ROND RISOTTO | C17: 0 | D17: 20 | E17: KG | F17: =+C17*D17 -> 0 | H17: 0 | I17: 0
A18: 20-12 | B18: SEMOULE | C18: 0 | D18: 60 | E18: KG | F18: =+C18*D18 -> 0 | H18: 0 | I18: 0
... A66: 20-60 | B66: PAIN AU LAIT PAQUETS DE 10 AU COLIS | C66: 0 | D66: 10 | E66: KG | F66: =+C66*D66 -> 0 | H66: 0 | I66: 0
B67: PRIX TOTAL ESTIMATIF ANNUEL HT | F67: =+SUM(F7:F66) -> 0
B68: TVA (5,5%) | F68: =+F67*0.055 -> 0
B69: PRIX TOTAL ESTIMATIF ANNUEL TTC | F69: =+F67+F68 -> 0
B71: JOURS DE COMMANDE | C71: LUNDI | D71: MARDI | E71: MERCREDI | F71: JEUDI | G71: VENDREDI
B72: JOURS DE LIVRAISONS | C72: LUNDI | D72: MARDI | E72: MERCREDI | F72: JEUDI | G72: VENDREDI

Sheet L21_surg
A2: 2025005 - FOURNITURE DE DENREES ALIMENTAIRES - COMMUNE DE SAVERDUN - LOT 21 SURGELE
A4: BORDEREAU DES PRIX VALANT DETAIL ESTIMATIF
A6: N° | B6: PRODUIT | C6: PRIX UNITAIRE HT PAR UNITE | D6: QUANTITES ESTIMATIVES / AN | E6: UNITE | F6: PRIX TOTAL ESTIMATIF ANNUEL HT | G6: CONDITIONNEMENT PROPOSE | H6: PRIX h.T. DU CONDITIONNEMENT PROPOSE | I6: PRIX t.T.c DU CONDITIONNEMENT PROPOSE
A7: 21-1 | B7: CREPE FROMENT SALEE 50 GRS | C7: 0 | D7: 350 | E7: UNITES | F7: =+C7*D7 -> 0 | H7: 0 | I7: 0
A8: 21-2 | B8: PAIN KEBAB ROND 110 GRS | C8: 0 | D8: 150 | E8: UNITES | F8: =+C8*D8 -> 0 | H8: 0 | I8: 0
A9: 21-3 | B9: PAIN PITA 100 GRS | C9: 0 | D9: 70 | E9: UNITES | F9: =+C9*D9 -> 0 | H9: 0 | I9: 0
A10: 21-4 | B10: PAIN PITA 110 GRS | C10: 0 | D10: 70 | E10: UNITES | F10: =+C10*D10 -> 0 | H10: 0 | I10: 0
A11: 21-5 | B11: PANINI 100 grs | C11: 0 | D11: 90 | E11: UNITES | F11: =+C11*D11 -> 0 | H11: 0 | I11: 0
A12: 21-6 | B12: PANINI 110 grs | C12: 0 | D12: 90 | E12: UNITES | F12: =+C12*D12 -> 0 | H12: 0 | I12: 0
A13: 21-7 | B13: CHAMPIGNONS PARIS France Sachet 2,5 kg | C13: 0 | D13: 20 | E13: UNITES | F13: =+C13*D13 -> 0 | H13: 0 | I13: 0
A14: 21-8 | B14: COCKTAIL FRUITS DE MER | C14: 0 | D14: 30 | E14: KG | F14: =+C14*D14 -> 0 | H14: 0 | I14: 0
A15: 21-9 | B15: CORDON BLEU POULET | C15: 0 | D15: 80 | E15: KG | F15: =+C15*D15 -> 0 | H15: 0 | I15: 0
A16: 21-10 | B16: CUBE FILET POISSON | C16: 0 | D16: 50 | E16: KG | F16: =+C16*D16 -> 0 | H16: 0 | I16: 0
A17: 21-11 | B17: EFFILOCHE CANARD CONFIT | C17: 0 | D17: 70 | E17: KG | F17: =+C17*D17 -> 0 | H17: 0 | I17: 0
A18: 21-12 | B18: ESCALOPE PANEE POULET | C18: 0 | D18: 40 | E18: KG | F18: =+C18*D18 -> 0 | H18: 0 | I18: 0
... A42: 21-36 | B42: GLACE POT 60 ml | C42: 0 | D42: 600 | E42: UNITES | F42: =+C42*D42 -> 0 | H42: 0 | I42: 0
B43: PRIX TOTAL ESTIMATIF ANNUEL HT | F43: =+SUM(F7:F42) -> 0
B44: TVA (5,5%) | F44: =+F43*0.055 -> 0
B45: PRIX TOTAL ESTIMATIF ANNUEL TTC | F45: =+F43+F44 -> 0
B47: JOURS DE COMMANDE | C47: LUNDI | D47: MARDI | E47: MERCREDI | F47: JEUDI | G47: VENDREDI
B48: JOURS DE LIVRAISONS | C48: LUNDI | D48: MARDI | E48: MERCREDI | F48: JEUDI | G48: VENDREDI

Sheet L22_surg AB
A2: 2025005 - FOURNITURE DE DENREES ALIMENTAIRES - COMMUNE DE SAVERDUN - LOT 22 SURGELE AB
A4: BORDEREAU DES PRIX VALANT DETAIL ESTIMATIF
A6: N° | B6: PRODUIT | C6: PRIX UNITAIRE HT PAR UNITE | D6: QUANTITES ESTIMATIVES / AN | E6: UNITE | F6: PRIX TOTAL ESTIMATIF ANNUEL HT | G6: CONDITIONNEMENT PROPOSE | H6: PRIX h.T. DU CONDITIONNEMENT PROPOSE | I6: PRIX t.T.c DU CONDITIONNEMENT PROPOSE
A7: 22-1 | B7: BOULETTE BŒUF | C7: 0 | D7: 60 | E7: KG | F7: =+C7*D7 -> 0 | H7: 0 | I7: 0
A8: 22-2 | B8: BROCOLIS FLEURETTE France Sachet 2,5 kg | C8: 0 | D8: 30 | E8: KG | F8: =+C8*D8 -> 0 | H8: 0 | I8: 0
A9: 22-3 | B9: CAROTTE RONDELLE France Sachet 2,5 kg | C9: 0 | D9: 50 | E9: KG | F9: =+C9*D9 -> 0 | H9: 0 | I9: 0
A10: 22-4 | B10: CHAMPIGNONS PARIS France Sachet 2,5 kg | C10: 0 | D10: 80 | E10: KG | F10: =+C10*D10 -> 0 | H10: 0 | I10: 0
A11: 22-5 | B11: CHOU-FLEUR FLEURETTE France Sachet 2,5 kg | C11: 0 | D11: 30 | E11: KG | F11: =+C11*D11 -> 0 | H11: 0 | I11: 0
A12: 22-6 | B12: CIBOULETTE Sachet 2,5 kg | C12: 0 | D12: 40 | E12: KG | F12: =+C12*D12 -> 0 | H12: 0 | I12: 0
A13: 22-7 | B13: COURGETTES France Sachet 2,5 kg | C13: 0 | D13: 60 | E13: KG | F13: =+C13*D13 -> 0 | H13: 0 | I13: 0
A14: 22-8 | B14: DES TOMATE | C14: 0 | D14: 50 | E14: KG | F14: =+C14*D14 -> 0 | H14: 0 | I14: 0
A15: 22-9 | B15: ECHALOTE CISELEE | C15: 0 | D15: 40 | E15: KG | F15: =+C15*D15 -> 0 | H15: 0 | I15: 0
A16: 22-10 | B16: EGRENE VEGETAL | C16: 0 | D16: 45 | E16: KG | F16: =+C16*D16 -> 0 | H16: 0 | I16: 0
A17: 22-11 | B17: FILET POULET | C17: 0 | D17: 30 | E17: KG | F17: =+C17*D17 -> 0 | H17: 0 | I17: 0
A18: 22-12 | B18: FILET SAUMON | C18: 0 | D18: 15 | E18: KG | F18: =+C18*D18 -> 0 | H18: 0 | I18: 0
... A36: 22-30 | B36: VIANDE BOEUF EGRAINEE 15% MG | C36: 0 | D36: 30 | E36: KG | F36: =+C36*D36 -> 0 | H36: 0 | I36: 0
B37: PRIX TOTAL ESTIMATIF ANNUEL HT | F37: =+SUM(F7:F36) -> 0
B38: TVA (5,5%) | F38: =+F37*0.055 -> 0
B39: PRIX TOTAL ESTIMATIF ANNUEL TTC | F39: =+F37+F38 -> 0
B41: JOURS DE COMMANDE | C41: LUNDI | D41: MARDI | E41: MERCREDI | F41: JEUDI | G41: VENDREDI
B42: JOURS DE LIVRAISONS | C42: LUNDI | D42: MARDI | E42: MERCREDI | F42: JEUDI | G42: VENDREDI

Sheet L23_glaces_artisanales
A2: 2025005 - FOURNITURE DE DENREES ALIMENTAIRES - COMMUNE DE SAVERDUN - LOT 23 GLACES ARTISANALES
A4: BORDEREAU DES PRIX VALANT DETAIL ESTIMATIF
A6: N° | B6: PRODUIT | C6: PRIX UNITAIRE HT PAR UNITE | D6: QUANTITES ESTIMATIVES / AN | E6: UNITE | F6: PRIX TOTAL ESTIMATIF ANNUEL HT | G6: CONDITIONNEMENT PROPOSE | H6: PRIX h.T. DU CONDITIONNEMENT PROPOSE | I6: PRIX t.T.c DU CONDITIONNEMENT PROPOSE
A7: 23-1 | B7: GLACE POTs individuels 60ml | C7: 0 | D7: 600 | E7: UNITES | F7: =+C7*D7 -> 0 | H7: 0 | I7: 0
B8: PRIX TOTAL ESTIMATIF ANNUEL HT | F8: =SUM(F7) -> 0
B9: TVA (5,5%) | F9: =+F8*0.055 -> 0
B10: PRIX TOTAL ESTIMATIF ANNUEL TTC | F10: =+F8+F9 -> 0
B12: JOURS DE COMMANDE | C12: LUNDI | D12: MARDI | E12: MERCREDI | F12: JEUDI | G12: VENDREDI
B13: JOURS DE LIVRAISONS | C13: LUNDI | D13: MARDI | E13: MERCREDI | F13: JEUDI | G13: VENDREDI

Sheet L24_poisson_frais
A2: 2025005 - FOURNITURE DE DENREES ALIMENTAIRES - COMMUNE DE SAVERDUN - LOT 24 POISSONS FRAIS
A4: BORDEREAU DES PRIX VALANT DETAIL ESTIMATIF
A6: N° | B6: PRODUIT | C6: PRIX UNITAIRE HT PAR UNITE | D6: QUANTITES ESTIMATIVES / AN | E6: UNITE | F6: PRIX TOTAL ESTIMATIF ANNUEL HT
A7: 24-1 | B7: cabillaud pêche durable | C7: 0 | D7: 50 | E7: KG | F7: =+C7*D7 -> 0
A8: 24-2 | B8: cabillaud MSC | C8: 0 | D8: 30 | E8: KG | F8: =+C8*D8 -> 0
A9: 24-3 | B9: merlu pêche durable | C9: 0 | D9: 40 | E9: KG | F9: =+C9*D9 -> 0
A10: 24-4 | B10: merlu MSC | C10: 0 | D10: 30 | E10: KG | F10: =+C10*D10 -> 0
A11: 24-5 | B11: Lieu noir durable | C11: 0 | D11: 40 | E11: KG | F11: =+C11*D11 -> 0
A12: 24-6 | B12: Lieu noir MSC | C12: 0 | D12: 30 | E12: KG | F12: =+C12*D12 -> 0
A13: 24-7 | B13: Colin pêche durable | C13: 0 | D13: 40 | E13: KG | F13: =+C13*D13 -> 0
A14: 24-8 | B14: Colin MSC | C14: 0 | D14: 30 | E14: KG | F14: =+C14*D14 -> 0
B15: PRIX TOTAL ESTIMATIF ANNUEL HT | F15: =SUM(F7:F14) -> 0
B16: TVA (5,5%) | F16: =+F15*0.055 -> 0
B17: PRIX TOTAL ESTIMATIF ANNUEL TTC | F17: =+F15+F16 -> 0
B19: JOURS DE COMMANDE | C19: LUNDI | D19: MARDI | E19: MERCREDI | F19: JEUDI | G19: VENDREDI
B20: JOURS DE LIVRAISONS | C20: LUNDI | D20: MARDI | E20: MERCREDI | F20: JEUDI | G20: VENDREDI
